{
 "cells": [
  {
   "cell_type": "code",
   "execution_count": 8,
   "id": "4fca4628",
   "metadata": {},
   "outputs": [
    {
     "name": "stdout",
     "output_type": "stream",
     "text": [
      "Collecting tensorflow\n",
      "  Using cached tensorflow-2.12.0-cp39-cp39-win_amd64.whl (1.9 kB)\n",
      "Collecting tensorflow-intel==2.12.0 (from tensorflow)\n",
      "  Using cached tensorflow_intel-2.12.0-cp39-cp39-win_amd64.whl (272.8 MB)\n",
      "Collecting absl-py>=1.0.0 (from tensorflow-intel==2.12.0->tensorflow)\n",
      "  Using cached absl_py-1.4.0-py3-none-any.whl (126 kB)\n",
      "Collecting astunparse>=1.6.0 (from tensorflow-intel==2.12.0->tensorflow)\n",
      "  Using cached astunparse-1.6.3-py2.py3-none-any.whl (12 kB)\n",
      "Requirement already satisfied: flatbuffers>=2.0 in c:\\users\\paul\\anaconda3\\lib\\site-packages (from tensorflow-intel==2.12.0->tensorflow) (23.5.9)\n",
      "Collecting gast<=0.4.0,>=0.2.1 (from tensorflow-intel==2.12.0->tensorflow)\n",
      "  Using cached gast-0.4.0-py3-none-any.whl (9.8 kB)\n",
      "Collecting google-pasta>=0.1.1 (from tensorflow-intel==2.12.0->tensorflow)\n",
      "  Using cached google_pasta-0.2.0-py3-none-any.whl (57 kB)\n",
      "Requirement already satisfied: h5py>=2.9.0 in c:\\users\\paul\\anaconda3\\lib\\site-packages (from tensorflow-intel==2.12.0->tensorflow) (3.7.0)\n",
      "Collecting jax>=0.3.15 (from tensorflow-intel==2.12.0->tensorflow)\n",
      "  Using cached jax-0.4.10-py3-none-any.whl\n",
      "Requirement already satisfied: libclang>=13.0.0 in c:\\users\\paul\\anaconda3\\lib\\site-packages (from tensorflow-intel==2.12.0->tensorflow) (16.0.0)\n",
      "Requirement already satisfied: numpy<1.24,>=1.22 in c:\\users\\paul\\anaconda3\\lib\\site-packages (from tensorflow-intel==2.12.0->tensorflow) (1.23.5)\n",
      "Collecting opt-einsum>=2.3.2 (from tensorflow-intel==2.12.0->tensorflow)\n",
      "  Using cached opt_einsum-3.3.0-py3-none-any.whl (65 kB)\n",
      "Requirement already satisfied: packaging in c:\\users\\paul\\anaconda3\\lib\\site-packages (from tensorflow-intel==2.12.0->tensorflow) (21.3)\n",
      "Requirement already satisfied: protobuf!=4.21.0,!=4.21.1,!=4.21.2,!=4.21.3,!=4.21.4,!=4.21.5,<5.0.0dev,>=3.20.3 in c:\\users\\paul\\anaconda3\\lib\\site-packages (from tensorflow-intel==2.12.0->tensorflow) (4.23.1)\n",
      "Requirement already satisfied: setuptools in c:\\users\\paul\\anaconda3\\lib\\site-packages (from tensorflow-intel==2.12.0->tensorflow) (67.6.0)\n",
      "Requirement already satisfied: six>=1.12.0 in c:\\users\\paul\\anaconda3\\lib\\site-packages (from tensorflow-intel==2.12.0->tensorflow) (1.16.0)\n",
      "Requirement already satisfied: termcolor>=1.1.0 in c:\\users\\paul\\anaconda3\\lib\\site-packages (from tensorflow-intel==2.12.0->tensorflow) (2.3.0)\n",
      "Requirement already satisfied: typing-extensions>=3.6.6 in c:\\users\\paul\\anaconda3\\lib\\site-packages (from tensorflow-intel==2.12.0->tensorflow) (4.3.0)\n",
      "Requirement already satisfied: wrapt<1.15,>=1.11.0 in c:\\users\\paul\\anaconda3\\lib\\site-packages (from tensorflow-intel==2.12.0->tensorflow) (1.14.1)\n",
      "Collecting grpcio<2.0,>=1.24.3 (from tensorflow-intel==2.12.0->tensorflow)\n",
      "  Using cached grpcio-1.54.2-cp39-cp39-win_amd64.whl (4.1 MB)\n",
      "Collecting tensorboard<2.13,>=2.12 (from tensorflow-intel==2.12.0->tensorflow)\n",
      "  Using cached tensorboard-2.12.3-py3-none-any.whl (5.6 MB)\n",
      "Requirement already satisfied: tensorflow-estimator<2.13,>=2.12.0 in c:\\users\\paul\\anaconda3\\lib\\site-packages (from tensorflow-intel==2.12.0->tensorflow) (2.12.0)\n",
      "Collecting keras<2.13,>=2.12.0 (from tensorflow-intel==2.12.0->tensorflow)\n",
      "  Using cached keras-2.12.0-py2.py3-none-any.whl (1.7 MB)\n",
      "Requirement already satisfied: tensorflow-io-gcs-filesystem>=0.23.1 in c:\\users\\paul\\anaconda3\\lib\\site-packages (from tensorflow-intel==2.12.0->tensorflow) (0.31.0)\n",
      "Requirement already satisfied: wheel<1.0,>=0.23.0 in c:\\users\\paul\\anaconda3\\lib\\site-packages (from astunparse>=1.6.0->tensorflow-intel==2.12.0->tensorflow) (0.37.1)\n",
      "Collecting ml-dtypes>=0.1.0 (from jax>=0.3.15->tensorflow-intel==2.12.0->tensorflow)\n",
      "  Using cached ml_dtypes-0.1.0-cp39-cp39-win_amd64.whl (120 kB)\n",
      "Requirement already satisfied: scipy>=1.7 in c:\\users\\paul\\anaconda3\\lib\\site-packages (from jax>=0.3.15->tensorflow-intel==2.12.0->tensorflow) (1.9.1)\n",
      "Collecting google-auth<3,>=1.6.3 (from tensorboard<2.13,>=2.12->tensorflow-intel==2.12.0->tensorflow)\n",
      "  Using cached google_auth-2.18.1-py2.py3-none-any.whl (178 kB)\n",
      "Collecting google-auth-oauthlib<1.1,>=0.5 (from tensorboard<2.13,>=2.12->tensorflow-intel==2.12.0->tensorflow)\n",
      "  Using cached google_auth_oauthlib-1.0.0-py2.py3-none-any.whl (18 kB)\n",
      "Requirement already satisfied: markdown>=2.6.8 in c:\\users\\paul\\anaconda3\\lib\\site-packages (from tensorboard<2.13,>=2.12->tensorflow-intel==2.12.0->tensorflow) (3.3.4)\n",
      "Requirement already satisfied: requests<3,>=2.21.0 in c:\\users\\paul\\anaconda3\\lib\\site-packages (from tensorboard<2.13,>=2.12->tensorflow-intel==2.12.0->tensorflow) (2.28.1)\n",
      "Requirement already satisfied: tensorboard-data-server<0.8.0,>=0.7.0 in c:\\users\\paul\\anaconda3\\lib\\site-packages (from tensorboard<2.13,>=2.12->tensorflow-intel==2.12.0->tensorflow) (0.7.0)\n",
      "Requirement already satisfied: werkzeug>=1.0.1 in c:\\users\\paul\\anaconda3\\lib\\site-packages (from tensorboard<2.13,>=2.12->tensorflow-intel==2.12.0->tensorflow) (2.0.3)\n",
      "Requirement already satisfied: pyparsing!=3.0.5,>=2.0.2 in c:\\users\\paul\\anaconda3\\lib\\site-packages (from packaging->tensorflow-intel==2.12.0->tensorflow) (3.0.9)\n",
      "Collecting cachetools<6.0,>=2.0.0 (from google-auth<3,>=1.6.3->tensorboard<2.13,>=2.12->tensorflow-intel==2.12.0->tensorflow)\n",
      "  Using cached cachetools-5.3.0-py3-none-any.whl (9.3 kB)\n",
      "Requirement already satisfied: pyasn1-modules>=0.2.1 in c:\\users\\paul\\anaconda3\\lib\\site-packages (from google-auth<3,>=1.6.3->tensorboard<2.13,>=2.12->tensorflow-intel==2.12.0->tensorflow) (0.2.8)\n",
      "Requirement already satisfied: urllib3<2.0 in c:\\users\\paul\\anaconda3\\lib\\site-packages (from google-auth<3,>=1.6.3->tensorboard<2.13,>=2.12->tensorflow-intel==2.12.0->tensorflow) (1.26.11)\n",
      "Requirement already satisfied: rsa<5,>=3.1.4 in c:\\users\\paul\\anaconda3\\lib\\site-packages (from google-auth<3,>=1.6.3->tensorboard<2.13,>=2.12->tensorflow-intel==2.12.0->tensorflow) (4.9)\n",
      "Collecting requests-oauthlib>=0.7.0 (from google-auth-oauthlib<1.1,>=0.5->tensorboard<2.13,>=2.12->tensorflow-intel==2.12.0->tensorflow)\n",
      "  Using cached requests_oauthlib-1.3.1-py2.py3-none-any.whl (23 kB)\n",
      "Requirement already satisfied: charset-normalizer<3,>=2 in c:\\users\\paul\\anaconda3\\lib\\site-packages (from requests<3,>=2.21.0->tensorboard<2.13,>=2.12->tensorflow-intel==2.12.0->tensorflow) (2.0.4)\n",
      "Requirement already satisfied: idna<4,>=2.5 in c:\\users\\paul\\anaconda3\\lib\\site-packages (from requests<3,>=2.21.0->tensorboard<2.13,>=2.12->tensorflow-intel==2.12.0->tensorflow) (3.3)\n",
      "Requirement already satisfied: certifi>=2017.4.17 in c:\\users\\paul\\anaconda3\\lib\\site-packages (from requests<3,>=2.21.0->tensorboard<2.13,>=2.12->tensorflow-intel==2.12.0->tensorflow) (2022.9.14)\n",
      "Requirement already satisfied: pyasn1<0.5.0,>=0.4.6 in c:\\users\\paul\\anaconda3\\lib\\site-packages (from pyasn1-modules>=0.2.1->google-auth<3,>=1.6.3->tensorboard<2.13,>=2.12->tensorflow-intel==2.12.0->tensorflow) (0.4.8)\n",
      "Requirement already satisfied: oauthlib>=3.0.0 in c:\\users\\paul\\anaconda3\\lib\\site-packages (from requests-oauthlib>=0.7.0->google-auth-oauthlib<1.1,>=0.5->tensorboard<2.13,>=2.12->tensorflow-intel==2.12.0->tensorflow) (3.2.2)\n",
      "Installing collected packages: opt-einsum, ml-dtypes, keras, grpcio, google-pasta, gast, cachetools, astunparse, absl-py, requests-oauthlib, jax, google-auth, google-auth-oauthlib, tensorboard, tensorflow-intel, tensorflow\n",
      "Successfully installed absl-py-1.4.0 astunparse-1.6.3 cachetools-5.3.0 gast-0.4.0 google-auth-2.18.1 google-auth-oauthlib-1.0.0 google-pasta-0.2.0 grpcio-1.54.2 jax-0.4.10 keras-2.12.0 ml-dtypes-0.1.0 opt-einsum-3.3.0 requests-oauthlib-1.3.1 tensorboard-2.12.3 tensorflow-2.12.0 tensorflow-intel-2.12.0\n"
     ]
    },
    {
     "name": "stderr",
     "output_type": "stream",
     "text": [
      "  WARNING: The script google-oauthlib-tool.exe is installed in 'C:\\Users\\Paul\\AppData\\Roaming\\Python\\Python39\\Scripts' which is not on PATH.\n",
      "  Consider adding this directory to PATH or, if you prefer to suppress this warning, use --no-warn-script-location.\n",
      "  WARNING: The script tensorboard.exe is installed in 'C:\\Users\\Paul\\AppData\\Roaming\\Python\\Python39\\Scripts' which is not on PATH.\n",
      "  Consider adding this directory to PATH or, if you prefer to suppress this warning, use --no-warn-script-location.\n",
      "  WARNING: The scripts estimator_ckpt_converter.exe, import_pb_to_tensorboard.exe, saved_model_cli.exe, tensorboard.exe, tf_upgrade_v2.exe, tflite_convert.exe, toco.exe and toco_from_protos.exe are installed in 'C:\\Users\\Paul\\AppData\\Roaming\\Python\\Python39\\Scripts' which is not on PATH.\n",
      "  Consider adding this directory to PATH or, if you prefer to suppress this warning, use --no-warn-script-location.\n"
     ]
    }
   ],
   "source": [
    "!pip install tensorflow --user"
   ]
  },
  {
   "cell_type": "code",
   "execution_count": 17,
   "id": "b81e61c9",
   "metadata": {},
   "outputs": [],
   "source": [
    "from scipy.sparse import load_npz\n",
    "import pandas as pd\n",
    "df_preprocessed_general = load_npz('./ds_salaries_BoWPreprocessing.npz')\n",
    "df_target = pd.read_csv(\"./ds_salaries_target.csv\")\n",
    "\n",
    "kfold = KFold(n_splits=10, shuffle=True, random_state=42)"
   ]
  },
  {
   "cell_type": "code",
   "execution_count": 21,
   "id": "81561f40",
   "metadata": {},
   "outputs": [
    {
     "name": "stderr",
     "output_type": "stream",
     "text": [
      "WARNING:absl:Skipping variable loading for optimizer 'Adam', because it has 5 variables whereas the saved optimizer has 1 variables. \n",
      "WARNING:absl:Skipping variable loading for optimizer 'Adam', because it has 5 variables whereas the saved optimizer has 1 variables. \n",
      "WARNING:absl:Skipping variable loading for optimizer 'Adam', because it has 5 variables whereas the saved optimizer has 1 variables. \n",
      "WARNING:absl:Skipping variable loading for optimizer 'Adam', because it has 5 variables whereas the saved optimizer has 1 variables. \n",
      "WARNING:absl:Skipping variable loading for optimizer 'Adam', because it has 5 variables whereas the saved optimizer has 1 variables. \n",
      "WARNING:absl:Skipping variable loading for optimizer 'Adam', because it has 5 variables whereas the saved optimizer has 1 variables. \n",
      "WARNING:absl:Skipping variable loading for optimizer 'Adam', because it has 5 variables whereas the saved optimizer has 1 variables. \n",
      "WARNING:absl:Skipping variable loading for optimizer 'Adam', because it has 5 variables whereas the saved optimizer has 1 variables. \n",
      "WARNING:absl:Skipping variable loading for optimizer 'Adam', because it has 5 variables whereas the saved optimizer has 1 variables. \n",
      "WARNING:absl:Skipping variable loading for optimizer 'Adam', because it has 5 variables whereas the saved optimizer has 1 variables. \n"
     ]
    },
    {
     "ename": "ValueError",
     "evalue": "\nAll the 10 fits failed.\nIt is very likely that your model is misconfigured.\nYou can try to debug the error by setting error_score='raise'.\n\nBelow are more details about the failures:\n--------------------------------------------------------------------------------\n9 fits failed with the following error:\nTraceback (most recent call last):\n  File \"C:\\Users\\Paul\\anaconda3\\lib\\site-packages\\sklearn\\model_selection\\_validation.py\", line 686, in _fit_and_score\n    estimator.fit(X_train, y_train, **fit_params)\n  File \"C:\\Users\\Paul\\anaconda3\\lib\\site-packages\\sklearn\\pipeline.py\", line 405, in fit\n    self._final_estimator.fit(Xt, y, **fit_params_last_step)\n  File \"C:\\Users\\Paul\\AppData\\Roaming\\Python\\Python39\\site-packages\\keras\\utils\\traceback_utils.py\", line 70, in error_handler\n    raise e.with_traceback(filtered_tb) from None\n  File \"C:\\Users\\Paul\\AppData\\Roaming\\Python\\Python39\\site-packages\\tensorflow\\python\\framework\\ops.py\", line 7262, in raise_from_not_ok_status\n    raise core._status_to_exception(e) from None  # pylint: disable=protected-access\ntensorflow.python.framework.errors_impl.InvalidArgumentError: {{function_node __wrapped__SerializeManySparse_device_/job:localhost/replica:0/task:0/device:CPU:0}} indices[1] = [0,15] is out of order. Many sparse ops require sorted indices.\n    Use `tf.sparse.reorder` to create a correctly ordered copy.\n\n [Op:SerializeManySparse]\n\n--------------------------------------------------------------------------------\n1 fits failed with the following error:\nTraceback (most recent call last):\n  File \"C:\\Users\\Paul\\anaconda3\\lib\\site-packages\\sklearn\\model_selection\\_validation.py\", line 686, in _fit_and_score\n    estimator.fit(X_train, y_train, **fit_params)\n  File \"C:\\Users\\Paul\\anaconda3\\lib\\site-packages\\sklearn\\pipeline.py\", line 405, in fit\n    self._final_estimator.fit(Xt, y, **fit_params_last_step)\n  File \"C:\\Users\\Paul\\AppData\\Roaming\\Python\\Python39\\site-packages\\keras\\utils\\traceback_utils.py\", line 70, in error_handler\n    raise e.with_traceback(filtered_tb) from None\n  File \"C:\\Users\\Paul\\AppData\\Roaming\\Python\\Python39\\site-packages\\tensorflow\\python\\framework\\ops.py\", line 7262, in raise_from_not_ok_status\n    raise core._status_to_exception(e) from None  # pylint: disable=protected-access\ntensorflow.python.framework.errors_impl.InvalidArgumentError: {{function_node __wrapped__SerializeManySparse_device_/job:localhost/replica:0/task:0/device:CPU:0}} indices[1] = [0,21] is out of order. Many sparse ops require sorted indices.\n    Use `tf.sparse.reorder` to create a correctly ordered copy.\n\n [Op:SerializeManySparse]\n",
     "output_type": "error",
     "traceback": [
      "\u001b[1;31m---------------------------------------------------------------------------\u001b[0m",
      "\u001b[1;31mValueError\u001b[0m                                Traceback (most recent call last)",
      "\u001b[1;32m~\\AppData\\Local\\Temp\\ipykernel_1728\\1369982652.py\u001b[0m in \u001b[0;36m<module>\u001b[1;34m\u001b[0m\n\u001b[0;32m     21\u001b[0m \u001b[0msteps\u001b[0m \u001b[1;33m=\u001b[0m \u001b[1;33m[\u001b[0m\u001b[1;33m(\u001b[0m\u001b[1;34m'estimator'\u001b[0m\u001b[1;33m,\u001b[0m \u001b[0mmodel\u001b[0m\u001b[1;33m)\u001b[0m\u001b[1;33m]\u001b[0m\u001b[1;33m\u001b[0m\u001b[1;33m\u001b[0m\u001b[0m\n\u001b[0;32m     22\u001b[0m \u001b[0mpipeline\u001b[0m \u001b[1;33m=\u001b[0m \u001b[0mPipeline\u001b[0m\u001b[1;33m(\u001b[0m\u001b[0msteps\u001b[0m\u001b[1;33m)\u001b[0m\u001b[1;33m\u001b[0m\u001b[1;33m\u001b[0m\u001b[0m\n\u001b[1;32m---> 23\u001b[1;33m \u001b[0mr2_scores\u001b[0m \u001b[1;33m=\u001b[0m \u001b[0mcross_val_score\u001b[0m\u001b[1;33m(\u001b[0m\u001b[0mpipeline\u001b[0m\u001b[1;33m,\u001b[0m \u001b[0mdf_preprocessed_general\u001b[0m\u001b[1;33m,\u001b[0m \u001b[0mdf_target\u001b[0m\u001b[1;33m.\u001b[0m\u001b[0mvalues\u001b[0m\u001b[1;33m.\u001b[0m\u001b[0mravel\u001b[0m\u001b[1;33m(\u001b[0m\u001b[1;33m)\u001b[0m\u001b[1;33m,\u001b[0m \u001b[0mcv\u001b[0m\u001b[1;33m=\u001b[0m\u001b[0mkfold\u001b[0m\u001b[1;33m,\u001b[0m \u001b[0mscoring\u001b[0m\u001b[1;33m=\u001b[0m\u001b[1;34m'r2'\u001b[0m\u001b[1;33m)\u001b[0m\u001b[1;33m\u001b[0m\u001b[1;33m\u001b[0m\u001b[0m\n\u001b[0m\u001b[0;32m     24\u001b[0m \u001b[0mmse_scores\u001b[0m \u001b[1;33m=\u001b[0m \u001b[1;33m-\u001b[0m\u001b[0mcross_val_score\u001b[0m\u001b[1;33m(\u001b[0m\u001b[0mpipeline\u001b[0m\u001b[1;33m,\u001b[0m \u001b[0mdf_preprocessed_general\u001b[0m\u001b[1;33m,\u001b[0m \u001b[0mdf_target\u001b[0m\u001b[1;33m.\u001b[0m\u001b[0mvalues\u001b[0m\u001b[1;33m.\u001b[0m\u001b[0mravel\u001b[0m\u001b[1;33m(\u001b[0m\u001b[1;33m)\u001b[0m\u001b[1;33m,\u001b[0m \u001b[0mcv\u001b[0m\u001b[1;33m=\u001b[0m\u001b[0mkfold\u001b[0m\u001b[1;33m,\u001b[0m \u001b[0mscoring\u001b[0m\u001b[1;33m=\u001b[0m\u001b[1;34m'neg_mean_squared_error'\u001b[0m\u001b[1;33m)\u001b[0m\u001b[1;33m\u001b[0m\u001b[1;33m\u001b[0m\u001b[0m\n\u001b[0;32m     25\u001b[0m \u001b[1;33m\u001b[0m\u001b[0m\n",
      "\u001b[1;32m~\\anaconda3\\lib\\site-packages\\sklearn\\model_selection\\_validation.py\u001b[0m in \u001b[0;36mcross_val_score\u001b[1;34m(estimator, X, y, groups, scoring, cv, n_jobs, verbose, fit_params, pre_dispatch, error_score)\u001b[0m\n\u001b[0;32m    513\u001b[0m     \u001b[0mscorer\u001b[0m \u001b[1;33m=\u001b[0m \u001b[0mcheck_scoring\u001b[0m\u001b[1;33m(\u001b[0m\u001b[0mestimator\u001b[0m\u001b[1;33m,\u001b[0m \u001b[0mscoring\u001b[0m\u001b[1;33m=\u001b[0m\u001b[0mscoring\u001b[0m\u001b[1;33m)\u001b[0m\u001b[1;33m\u001b[0m\u001b[1;33m\u001b[0m\u001b[0m\n\u001b[0;32m    514\u001b[0m \u001b[1;33m\u001b[0m\u001b[0m\n\u001b[1;32m--> 515\u001b[1;33m     cv_results = cross_validate(\n\u001b[0m\u001b[0;32m    516\u001b[0m         \u001b[0mestimator\u001b[0m\u001b[1;33m=\u001b[0m\u001b[0mestimator\u001b[0m\u001b[1;33m,\u001b[0m\u001b[1;33m\u001b[0m\u001b[1;33m\u001b[0m\u001b[0m\n\u001b[0;32m    517\u001b[0m         \u001b[0mX\u001b[0m\u001b[1;33m=\u001b[0m\u001b[0mX\u001b[0m\u001b[1;33m,\u001b[0m\u001b[1;33m\u001b[0m\u001b[1;33m\u001b[0m\u001b[0m\n",
      "\u001b[1;32m~\\anaconda3\\lib\\site-packages\\sklearn\\model_selection\\_validation.py\u001b[0m in \u001b[0;36mcross_validate\u001b[1;34m(estimator, X, y, groups, scoring, cv, n_jobs, verbose, fit_params, pre_dispatch, return_train_score, return_estimator, error_score)\u001b[0m\n\u001b[0;32m    283\u001b[0m     )\n\u001b[0;32m    284\u001b[0m \u001b[1;33m\u001b[0m\u001b[0m\n\u001b[1;32m--> 285\u001b[1;33m     \u001b[0m_warn_or_raise_about_fit_failures\u001b[0m\u001b[1;33m(\u001b[0m\u001b[0mresults\u001b[0m\u001b[1;33m,\u001b[0m \u001b[0merror_score\u001b[0m\u001b[1;33m)\u001b[0m\u001b[1;33m\u001b[0m\u001b[1;33m\u001b[0m\u001b[0m\n\u001b[0m\u001b[0;32m    286\u001b[0m \u001b[1;33m\u001b[0m\u001b[0m\n\u001b[0;32m    287\u001b[0m     \u001b[1;31m# For callabe scoring, the return type is only know after calling. If the\u001b[0m\u001b[1;33m\u001b[0m\u001b[1;33m\u001b[0m\u001b[0m\n",
      "\u001b[1;32m~\\anaconda3\\lib\\site-packages\\sklearn\\model_selection\\_validation.py\u001b[0m in \u001b[0;36m_warn_or_raise_about_fit_failures\u001b[1;34m(results, error_score)\u001b[0m\n\u001b[0;32m    365\u001b[0m                 \u001b[1;34mf\"Below are more details about the failures:\\n{fit_errors_summary}\"\u001b[0m\u001b[1;33m\u001b[0m\u001b[1;33m\u001b[0m\u001b[0m\n\u001b[0;32m    366\u001b[0m             )\n\u001b[1;32m--> 367\u001b[1;33m             \u001b[1;32mraise\u001b[0m \u001b[0mValueError\u001b[0m\u001b[1;33m(\u001b[0m\u001b[0mall_fits_failed_message\u001b[0m\u001b[1;33m)\u001b[0m\u001b[1;33m\u001b[0m\u001b[1;33m\u001b[0m\u001b[0m\n\u001b[0m\u001b[0;32m    368\u001b[0m \u001b[1;33m\u001b[0m\u001b[0m\n\u001b[0;32m    369\u001b[0m         \u001b[1;32melse\u001b[0m\u001b[1;33m:\u001b[0m\u001b[1;33m\u001b[0m\u001b[1;33m\u001b[0m\u001b[0m\n",
      "\u001b[1;31mValueError\u001b[0m: \nAll the 10 fits failed.\nIt is very likely that your model is misconfigured.\nYou can try to debug the error by setting error_score='raise'.\n\nBelow are more details about the failures:\n--------------------------------------------------------------------------------\n9 fits failed with the following error:\nTraceback (most recent call last):\n  File \"C:\\Users\\Paul\\anaconda3\\lib\\site-packages\\sklearn\\model_selection\\_validation.py\", line 686, in _fit_and_score\n    estimator.fit(X_train, y_train, **fit_params)\n  File \"C:\\Users\\Paul\\anaconda3\\lib\\site-packages\\sklearn\\pipeline.py\", line 405, in fit\n    self._final_estimator.fit(Xt, y, **fit_params_last_step)\n  File \"C:\\Users\\Paul\\AppData\\Roaming\\Python\\Python39\\site-packages\\keras\\utils\\traceback_utils.py\", line 70, in error_handler\n    raise e.with_traceback(filtered_tb) from None\n  File \"C:\\Users\\Paul\\AppData\\Roaming\\Python\\Python39\\site-packages\\tensorflow\\python\\framework\\ops.py\", line 7262, in raise_from_not_ok_status\n    raise core._status_to_exception(e) from None  # pylint: disable=protected-access\ntensorflow.python.framework.errors_impl.InvalidArgumentError: {{function_node __wrapped__SerializeManySparse_device_/job:localhost/replica:0/task:0/device:CPU:0}} indices[1] = [0,15] is out of order. Many sparse ops require sorted indices.\n    Use `tf.sparse.reorder` to create a correctly ordered copy.\n\n [Op:SerializeManySparse]\n\n--------------------------------------------------------------------------------\n1 fits failed with the following error:\nTraceback (most recent call last):\n  File \"C:\\Users\\Paul\\anaconda3\\lib\\site-packages\\sklearn\\model_selection\\_validation.py\", line 686, in _fit_and_score\n    estimator.fit(X_train, y_train, **fit_params)\n  File \"C:\\Users\\Paul\\anaconda3\\lib\\site-packages\\sklearn\\pipeline.py\", line 405, in fit\n    self._final_estimator.fit(Xt, y, **fit_params_last_step)\n  File \"C:\\Users\\Paul\\AppData\\Roaming\\Python\\Python39\\site-packages\\keras\\utils\\traceback_utils.py\", line 70, in error_handler\n    raise e.with_traceback(filtered_tb) from None\n  File \"C:\\Users\\Paul\\AppData\\Roaming\\Python\\Python39\\site-packages\\tensorflow\\python\\framework\\ops.py\", line 7262, in raise_from_not_ok_status\n    raise core._status_to_exception(e) from None  # pylint: disable=protected-access\ntensorflow.python.framework.errors_impl.InvalidArgumentError: {{function_node __wrapped__SerializeManySparse_device_/job:localhost/replica:0/task:0/device:CPU:0}} indices[1] = [0,21] is out of order. Many sparse ops require sorted indices.\n    Use `tf.sparse.reorder` to create a correctly ordered copy.\n\n [Op:SerializeManySparse]\n"
     ]
    }
   ],
   "source": [
    "import tensorflow as tf\n",
    "from tensorflow.keras import layers\n",
    "from sklearn.pipeline import Pipeline\n",
    "from sklearn.model_selection import cross_val_score, KFold\n",
    "import numpy as np\n",
    "\n",
    "# Define the input dimension based on your data\n",
    "input_dim = 280\n",
    "\n",
    "# Define your preprocessed data and target variable\n",
    "df_preprocessed_general = df_preprocessed_general\n",
    "df_target = df_target\n",
    "\n",
    "# Modell erstellen \n",
    "model = tf.keras.Sequential() \n",
    "model.add(layers.Dense(64, activation='relu', input_shape=(input_dim,)))\n",
    "\n",
    "# Compile the model\n",
    "model.compile(optimizer='adam', loss='mse')  # Set the appropriate optimizer and loss function\n",
    "\n",
    "steps = [('estimator', model)]  \n",
    "pipeline = Pipeline(steps)  \n",
    "r2_scores = cross_val_score(pipeline, df_preprocessed_general, df_target.values.ravel(), cv=kfold, scoring='r2') \n",
    "mse_scores = -cross_val_score(pipeline, df_preprocessed_general, df_target.values.ravel(), cv=kfold, scoring='neg_mean_squared_error')  \n",
    "\n",
    "print(\"General Preprocessing:\") \n",
    "print(\"ANNs MLP Regressor R2: \", np.mean(r2_scores)) \n",
    "print(\"ANNs MLP Regressor MSE: \", np.mean(mse_scores))"
   ]
  },
  {
   "cell_type": "code",
   "execution_count": 23,
   "id": "a826c678",
   "metadata": {},
   "outputs": [
    {
     "name": "stderr",
     "output_type": "stream",
     "text": [
      "C:\\Users\\Paul\\AppData\\Local\\Temp\\ipykernel_1728\\3129219867.py:15: DeprecationWarning: KerasRegressor is deprecated, use Sci-Keras (https://github.com/adriangb/scikeras) instead. See https://www.adriangb.com/scikeras/stable/migration.html for help migrating.\n",
      "  estimator = tf.keras.wrappers.scikit_learn.KerasRegressor(build_fn=lambda: model, epochs=10, batch_size=32, verbose=0)\n"
     ]
    },
    {
     "ename": "ValueError",
     "evalue": "\nAll the 10 fits failed.\nIt is very likely that your model is misconfigured.\nYou can try to debug the error by setting error_score='raise'.\n\nBelow are more details about the failures:\n--------------------------------------------------------------------------------\n9 fits failed with the following error:\nTraceback (most recent call last):\n  File \"C:\\Users\\Paul\\anaconda3\\lib\\site-packages\\sklearn\\model_selection\\_validation.py\", line 686, in _fit_and_score\n    estimator.fit(X_train, y_train, **fit_params)\n  File \"C:\\Users\\Paul\\anaconda3\\lib\\site-packages\\sklearn\\pipeline.py\", line 405, in fit\n    self._final_estimator.fit(Xt, y, **fit_params_last_step)\n  File \"C:\\Users\\Paul\\AppData\\Roaming\\Python\\Python39\\site-packages\\keras\\wrappers\\scikit_learn.py\", line 175, in fit\n    history = self.model.fit(x, y, **fit_args)\n  File \"C:\\Users\\Paul\\AppData\\Roaming\\Python\\Python39\\site-packages\\keras\\utils\\traceback_utils.py\", line 70, in error_handler\n    raise e.with_traceback(filtered_tb) from None\n  File \"C:\\Users\\Paul\\AppData\\Roaming\\Python\\Python39\\site-packages\\tensorflow\\python\\framework\\ops.py\", line 7262, in raise_from_not_ok_status\n    raise core._status_to_exception(e) from None  # pylint: disable=protected-access\ntensorflow.python.framework.errors_impl.InvalidArgumentError: {{function_node __wrapped__SerializeManySparse_device_/job:localhost/replica:0/task:0/device:CPU:0}} indices[1] = [0,15] is out of order. Many sparse ops require sorted indices.\n    Use `tf.sparse.reorder` to create a correctly ordered copy.\n\n [Op:SerializeManySparse]\n\n--------------------------------------------------------------------------------\n1 fits failed with the following error:\nTraceback (most recent call last):\n  File \"C:\\Users\\Paul\\anaconda3\\lib\\site-packages\\sklearn\\model_selection\\_validation.py\", line 686, in _fit_and_score\n    estimator.fit(X_train, y_train, **fit_params)\n  File \"C:\\Users\\Paul\\anaconda3\\lib\\site-packages\\sklearn\\pipeline.py\", line 405, in fit\n    self._final_estimator.fit(Xt, y, **fit_params_last_step)\n  File \"C:\\Users\\Paul\\AppData\\Roaming\\Python\\Python39\\site-packages\\keras\\wrappers\\scikit_learn.py\", line 175, in fit\n    history = self.model.fit(x, y, **fit_args)\n  File \"C:\\Users\\Paul\\AppData\\Roaming\\Python\\Python39\\site-packages\\keras\\utils\\traceback_utils.py\", line 70, in error_handler\n    raise e.with_traceback(filtered_tb) from None\n  File \"C:\\Users\\Paul\\AppData\\Roaming\\Python\\Python39\\site-packages\\tensorflow\\python\\framework\\ops.py\", line 7262, in raise_from_not_ok_status\n    raise core._status_to_exception(e) from None  # pylint: disable=protected-access\ntensorflow.python.framework.errors_impl.InvalidArgumentError: {{function_node __wrapped__SerializeManySparse_device_/job:localhost/replica:0/task:0/device:CPU:0}} indices[1] = [0,21] is out of order. Many sparse ops require sorted indices.\n    Use `tf.sparse.reorder` to create a correctly ordered copy.\n\n [Op:SerializeManySparse]\n",
     "output_type": "error",
     "traceback": [
      "\u001b[1;31m---------------------------------------------------------------------------\u001b[0m",
      "\u001b[1;31mValueError\u001b[0m                                Traceback (most recent call last)",
      "\u001b[1;32m~\\AppData\\Local\\Temp\\ipykernel_1728\\3129219867.py\u001b[0m in \u001b[0;36m<module>\u001b[1;34m\u001b[0m\n\u001b[0;32m     19\u001b[0m \u001b[1;33m\u001b[0m\u001b[0m\n\u001b[0;32m     20\u001b[0m \u001b[1;31m#Kreuzvalidierung und Bewertung\u001b[0m\u001b[1;33m\u001b[0m\u001b[1;33m\u001b[0m\u001b[0m\n\u001b[1;32m---> 21\u001b[1;33m \u001b[0mr2_scores\u001b[0m \u001b[1;33m=\u001b[0m \u001b[0mcross_val_score\u001b[0m\u001b[1;33m(\u001b[0m\u001b[0mpipeline\u001b[0m\u001b[1;33m,\u001b[0m \u001b[0mdf_preprocessed_general\u001b[0m\u001b[1;33m,\u001b[0m \u001b[0mdf_target\u001b[0m\u001b[1;33m.\u001b[0m\u001b[0mvalues\u001b[0m\u001b[1;33m.\u001b[0m\u001b[0mravel\u001b[0m\u001b[1;33m(\u001b[0m\u001b[1;33m)\u001b[0m\u001b[1;33m,\u001b[0m \u001b[0mcv\u001b[0m\u001b[1;33m=\u001b[0m\u001b[0mkfold\u001b[0m\u001b[1;33m,\u001b[0m \u001b[0mscoring\u001b[0m\u001b[1;33m=\u001b[0m\u001b[1;34m'r2'\u001b[0m\u001b[1;33m)\u001b[0m\u001b[1;33m\u001b[0m\u001b[1;33m\u001b[0m\u001b[0m\n\u001b[0m\u001b[0;32m     22\u001b[0m \u001b[0mmse_scores\u001b[0m \u001b[1;33m=\u001b[0m \u001b[1;33m-\u001b[0m\u001b[0mcross_val_score\u001b[0m\u001b[1;33m(\u001b[0m\u001b[0mpipeline\u001b[0m\u001b[1;33m,\u001b[0m \u001b[0mdf_preprocessed_general\u001b[0m\u001b[1;33m,\u001b[0m \u001b[0mdf_target\u001b[0m\u001b[1;33m.\u001b[0m\u001b[0mvalues\u001b[0m\u001b[1;33m.\u001b[0m\u001b[0mravel\u001b[0m\u001b[1;33m(\u001b[0m\u001b[1;33m)\u001b[0m\u001b[1;33m,\u001b[0m \u001b[0mcv\u001b[0m\u001b[1;33m=\u001b[0m\u001b[0mkfold\u001b[0m\u001b[1;33m,\u001b[0m \u001b[0mscoring\u001b[0m\u001b[1;33m=\u001b[0m\u001b[1;34m'neg_mean_squared_error'\u001b[0m\u001b[1;33m)\u001b[0m\u001b[1;33m\u001b[0m\u001b[1;33m\u001b[0m\u001b[0m\n\u001b[0;32m     23\u001b[0m \u001b[1;33m\u001b[0m\u001b[0m\n",
      "\u001b[1;32m~\\anaconda3\\lib\\site-packages\\sklearn\\model_selection\\_validation.py\u001b[0m in \u001b[0;36mcross_val_score\u001b[1;34m(estimator, X, y, groups, scoring, cv, n_jobs, verbose, fit_params, pre_dispatch, error_score)\u001b[0m\n\u001b[0;32m    513\u001b[0m     \u001b[0mscorer\u001b[0m \u001b[1;33m=\u001b[0m \u001b[0mcheck_scoring\u001b[0m\u001b[1;33m(\u001b[0m\u001b[0mestimator\u001b[0m\u001b[1;33m,\u001b[0m \u001b[0mscoring\u001b[0m\u001b[1;33m=\u001b[0m\u001b[0mscoring\u001b[0m\u001b[1;33m)\u001b[0m\u001b[1;33m\u001b[0m\u001b[1;33m\u001b[0m\u001b[0m\n\u001b[0;32m    514\u001b[0m \u001b[1;33m\u001b[0m\u001b[0m\n\u001b[1;32m--> 515\u001b[1;33m     cv_results = cross_validate(\n\u001b[0m\u001b[0;32m    516\u001b[0m         \u001b[0mestimator\u001b[0m\u001b[1;33m=\u001b[0m\u001b[0mestimator\u001b[0m\u001b[1;33m,\u001b[0m\u001b[1;33m\u001b[0m\u001b[1;33m\u001b[0m\u001b[0m\n\u001b[0;32m    517\u001b[0m         \u001b[0mX\u001b[0m\u001b[1;33m=\u001b[0m\u001b[0mX\u001b[0m\u001b[1;33m,\u001b[0m\u001b[1;33m\u001b[0m\u001b[1;33m\u001b[0m\u001b[0m\n",
      "\u001b[1;32m~\\anaconda3\\lib\\site-packages\\sklearn\\model_selection\\_validation.py\u001b[0m in \u001b[0;36mcross_validate\u001b[1;34m(estimator, X, y, groups, scoring, cv, n_jobs, verbose, fit_params, pre_dispatch, return_train_score, return_estimator, error_score)\u001b[0m\n\u001b[0;32m    283\u001b[0m     )\n\u001b[0;32m    284\u001b[0m \u001b[1;33m\u001b[0m\u001b[0m\n\u001b[1;32m--> 285\u001b[1;33m     \u001b[0m_warn_or_raise_about_fit_failures\u001b[0m\u001b[1;33m(\u001b[0m\u001b[0mresults\u001b[0m\u001b[1;33m,\u001b[0m \u001b[0merror_score\u001b[0m\u001b[1;33m)\u001b[0m\u001b[1;33m\u001b[0m\u001b[1;33m\u001b[0m\u001b[0m\n\u001b[0m\u001b[0;32m    286\u001b[0m \u001b[1;33m\u001b[0m\u001b[0m\n\u001b[0;32m    287\u001b[0m     \u001b[1;31m# For callabe scoring, the return type is only know after calling. If the\u001b[0m\u001b[1;33m\u001b[0m\u001b[1;33m\u001b[0m\u001b[0m\n",
      "\u001b[1;32m~\\anaconda3\\lib\\site-packages\\sklearn\\model_selection\\_validation.py\u001b[0m in \u001b[0;36m_warn_or_raise_about_fit_failures\u001b[1;34m(results, error_score)\u001b[0m\n\u001b[0;32m    365\u001b[0m                 \u001b[1;34mf\"Below are more details about the failures:\\n{fit_errors_summary}\"\u001b[0m\u001b[1;33m\u001b[0m\u001b[1;33m\u001b[0m\u001b[0m\n\u001b[0;32m    366\u001b[0m             )\n\u001b[1;32m--> 367\u001b[1;33m             \u001b[1;32mraise\u001b[0m \u001b[0mValueError\u001b[0m\u001b[1;33m(\u001b[0m\u001b[0mall_fits_failed_message\u001b[0m\u001b[1;33m)\u001b[0m\u001b[1;33m\u001b[0m\u001b[1;33m\u001b[0m\u001b[0m\n\u001b[0m\u001b[0;32m    368\u001b[0m \u001b[1;33m\u001b[0m\u001b[0m\n\u001b[0;32m    369\u001b[0m         \u001b[1;32melse\u001b[0m\u001b[1;33m:\u001b[0m\u001b[1;33m\u001b[0m\u001b[1;33m\u001b[0m\u001b[0m\n",
      "\u001b[1;31mValueError\u001b[0m: \nAll the 10 fits failed.\nIt is very likely that your model is misconfigured.\nYou can try to debug the error by setting error_score='raise'.\n\nBelow are more details about the failures:\n--------------------------------------------------------------------------------\n9 fits failed with the following error:\nTraceback (most recent call last):\n  File \"C:\\Users\\Paul\\anaconda3\\lib\\site-packages\\sklearn\\model_selection\\_validation.py\", line 686, in _fit_and_score\n    estimator.fit(X_train, y_train, **fit_params)\n  File \"C:\\Users\\Paul\\anaconda3\\lib\\site-packages\\sklearn\\pipeline.py\", line 405, in fit\n    self._final_estimator.fit(Xt, y, **fit_params_last_step)\n  File \"C:\\Users\\Paul\\AppData\\Roaming\\Python\\Python39\\site-packages\\keras\\wrappers\\scikit_learn.py\", line 175, in fit\n    history = self.model.fit(x, y, **fit_args)\n  File \"C:\\Users\\Paul\\AppData\\Roaming\\Python\\Python39\\site-packages\\keras\\utils\\traceback_utils.py\", line 70, in error_handler\n    raise e.with_traceback(filtered_tb) from None\n  File \"C:\\Users\\Paul\\AppData\\Roaming\\Python\\Python39\\site-packages\\tensorflow\\python\\framework\\ops.py\", line 7262, in raise_from_not_ok_status\n    raise core._status_to_exception(e) from None  # pylint: disable=protected-access\ntensorflow.python.framework.errors_impl.InvalidArgumentError: {{function_node __wrapped__SerializeManySparse_device_/job:localhost/replica:0/task:0/device:CPU:0}} indices[1] = [0,15] is out of order. Many sparse ops require sorted indices.\n    Use `tf.sparse.reorder` to create a correctly ordered copy.\n\n [Op:SerializeManySparse]\n\n--------------------------------------------------------------------------------\n1 fits failed with the following error:\nTraceback (most recent call last):\n  File \"C:\\Users\\Paul\\anaconda3\\lib\\site-packages\\sklearn\\model_selection\\_validation.py\", line 686, in _fit_and_score\n    estimator.fit(X_train, y_train, **fit_params)\n  File \"C:\\Users\\Paul\\anaconda3\\lib\\site-packages\\sklearn\\pipeline.py\", line 405, in fit\n    self._final_estimator.fit(Xt, y, **fit_params_last_step)\n  File \"C:\\Users\\Paul\\AppData\\Roaming\\Python\\Python39\\site-packages\\keras\\wrappers\\scikit_learn.py\", line 175, in fit\n    history = self.model.fit(x, y, **fit_args)\n  File \"C:\\Users\\Paul\\AppData\\Roaming\\Python\\Python39\\site-packages\\keras\\utils\\traceback_utils.py\", line 70, in error_handler\n    raise e.with_traceback(filtered_tb) from None\n  File \"C:\\Users\\Paul\\AppData\\Roaming\\Python\\Python39\\site-packages\\tensorflow\\python\\framework\\ops.py\", line 7262, in raise_from_not_ok_status\n    raise core._status_to_exception(e) from None  # pylint: disable=protected-access\ntensorflow.python.framework.errors_impl.InvalidArgumentError: {{function_node __wrapped__SerializeManySparse_device_/job:localhost/replica:0/task:0/device:CPU:0}} indices[1] = [0,21] is out of order. Many sparse ops require sorted indices.\n    Use `tf.sparse.reorder` to create a correctly ordered copy.\n\n [Op:SerializeManySparse]\n"
     ]
    }
   ],
   "source": [
    "import tensorflow as tf\n",
    "from tensorflow.keras import layers\n",
    "from sklearn.pipeline import Pipeline\n",
    "from sklearn.model_selection import cross_val_score\n",
    "\n",
    "#Modell erstellen\n",
    "model = tf.keras.Sequential()\n",
    "model.add(layers.Dense(10, activation='relu', input_shape=(input_dim,)))\n",
    "model.add(layers.Dense(1))  # Annahme: Regressionsmodell mit einer Ausgabegröße\n",
    "\n",
    "#Modell kompilieren\n",
    "model.compile(optimizer='adam', loss='mean_squared_error')\n",
    "\n",
    "#Estimator für TensorFlow-Modell\n",
    "estimator = tf.keras.wrappers.scikit_learn.KerasRegressor(build_fn=lambda: model, epochs=10, batch_size=32, verbose=0)\n",
    "\n",
    "steps = [('estimator', estimator)]\n",
    "pipeline = Pipeline(steps)\n",
    "\n",
    "#Kreuzvalidierung und Bewertung\n",
    "r2_scores = cross_val_score(pipeline, df_preprocessed_general, df_target.values.ravel(), cv=kfold, scoring='r2')\n",
    "mse_scores = -cross_val_score(pipeline, df_preprocessed_general, df_target.values.ravel(), cv=kfold, scoring='neg_mean_squared_error')\n",
    "\n",
    "print(\"General Preprocessing:\")\n",
    "print(\"ANNs MLP Regressor R2: \", np.mean(r2_scores))\n",
    "print(\"ANNs MLP Regressor MSE: \", np.mean(mse_scores))"
   ]
  },
  {
   "cell_type": "code",
   "execution_count": 31,
   "id": "0d3f8bc0",
   "metadata": {},
   "outputs": [
    {
     "name": "stdout",
     "output_type": "stream",
     "text": [
      "2.12.0\n"
     ]
    }
   ],
   "source": [
    "import tensorflow as tf\n",
    "print(tf.__version__)\n",
    "import numpy as np\n",
    "import matplotlib.pyplot as plt"
   ]
  },
  {
   "cell_type": "code",
   "execution_count": 32,
   "id": "a244f713",
   "metadata": {},
   "outputs": [
    {
     "ename": "ValueError",
     "evalue": "Failed to find data adapter that can handle input: <class 'scipy.sparse._csr.csr_matrix'>, <class 'pandas.core.frame.DataFrame'>",
     "output_type": "error",
     "traceback": [
      "\u001b[1;31m---------------------------------------------------------------------------\u001b[0m",
      "\u001b[1;31mValueError\u001b[0m                                Traceback (most recent call last)",
      "\u001b[1;32m~\\AppData\\Local\\Temp\\ipykernel_1728\\2310754147.py\u001b[0m in \u001b[0;36m<module>\u001b[1;34m\u001b[0m\n\u001b[0;32m      7\u001b[0m               \u001b[0moptimizer\u001b[0m \u001b[1;33m=\u001b[0m \u001b[0mtf\u001b[0m\u001b[1;33m.\u001b[0m\u001b[0mkeras\u001b[0m\u001b[1;33m.\u001b[0m\u001b[0moptimizers\u001b[0m\u001b[1;33m.\u001b[0m\u001b[0mSGD\u001b[0m\u001b[1;33m(\u001b[0m\u001b[1;33m)\u001b[0m\u001b[1;33m,\u001b[0m \u001b[1;31m#stochastic GD\u001b[0m\u001b[1;33m\u001b[0m\u001b[1;33m\u001b[0m\u001b[0m\n\u001b[0;32m      8\u001b[0m               metrics = ['mae'])\n\u001b[1;32m----> 9\u001b[1;33m \u001b[0mmodel\u001b[0m\u001b[1;33m.\u001b[0m\u001b[0mfit\u001b[0m\u001b[1;33m(\u001b[0m \u001b[0mdf_preprocessed_general\u001b[0m\u001b[1;33m,\u001b[0m \u001b[0mdf_target\u001b[0m\u001b[1;33m,\u001b[0m \u001b[0mepochs\u001b[0m \u001b[1;33m=\u001b[0m \u001b[1;36m10\u001b[0m\u001b[1;33m)\u001b[0m\u001b[1;33m\u001b[0m\u001b[1;33m\u001b[0m\u001b[0m\n\u001b[0m",
      "\u001b[1;32m~\\AppData\\Roaming\\Python\\Python39\\site-packages\\keras\\utils\\traceback_utils.py\u001b[0m in \u001b[0;36merror_handler\u001b[1;34m(*args, **kwargs)\u001b[0m\n\u001b[0;32m     68\u001b[0m             \u001b[1;31m# To get the full stack trace, call:\u001b[0m\u001b[1;33m\u001b[0m\u001b[1;33m\u001b[0m\u001b[0m\n\u001b[0;32m     69\u001b[0m             \u001b[1;31m# `tf.debugging.disable_traceback_filtering()`\u001b[0m\u001b[1;33m\u001b[0m\u001b[1;33m\u001b[0m\u001b[0m\n\u001b[1;32m---> 70\u001b[1;33m             \u001b[1;32mraise\u001b[0m \u001b[0me\u001b[0m\u001b[1;33m.\u001b[0m\u001b[0mwith_traceback\u001b[0m\u001b[1;33m(\u001b[0m\u001b[0mfiltered_tb\u001b[0m\u001b[1;33m)\u001b[0m \u001b[1;32mfrom\u001b[0m \u001b[1;32mNone\u001b[0m\u001b[1;33m\u001b[0m\u001b[1;33m\u001b[0m\u001b[0m\n\u001b[0m\u001b[0;32m     71\u001b[0m         \u001b[1;32mfinally\u001b[0m\u001b[1;33m:\u001b[0m\u001b[1;33m\u001b[0m\u001b[1;33m\u001b[0m\u001b[0m\n\u001b[0;32m     72\u001b[0m             \u001b[1;32mdel\u001b[0m \u001b[0mfiltered_tb\u001b[0m\u001b[1;33m\u001b[0m\u001b[1;33m\u001b[0m\u001b[0m\n",
      "\u001b[1;32m~\\AppData\\Roaming\\Python\\Python39\\site-packages\\keras\\engine\\data_adapter.py\u001b[0m in \u001b[0;36mselect_data_adapter\u001b[1;34m(x, y)\u001b[0m\n\u001b[0;32m   1080\u001b[0m     \u001b[1;32mif\u001b[0m \u001b[1;32mnot\u001b[0m \u001b[0madapter_cls\u001b[0m\u001b[1;33m:\u001b[0m\u001b[1;33m\u001b[0m\u001b[1;33m\u001b[0m\u001b[0m\n\u001b[0;32m   1081\u001b[0m         \u001b[1;31m# TODO(scottzhu): This should be a less implementation-specific error.\u001b[0m\u001b[1;33m\u001b[0m\u001b[1;33m\u001b[0m\u001b[0m\n\u001b[1;32m-> 1082\u001b[1;33m         raise ValueError(\n\u001b[0m\u001b[0;32m   1083\u001b[0m             \"Failed to find data adapter that can handle input: {}, {}\".format(\n\u001b[0;32m   1084\u001b[0m                 \u001b[0m_type_name\u001b[0m\u001b[1;33m(\u001b[0m\u001b[0mx\u001b[0m\u001b[1;33m)\u001b[0m\u001b[1;33m,\u001b[0m \u001b[0m_type_name\u001b[0m\u001b[1;33m(\u001b[0m\u001b[0my\u001b[0m\u001b[1;33m)\u001b[0m\u001b[1;33m\u001b[0m\u001b[1;33m\u001b[0m\u001b[0m\n",
      "\u001b[1;31mValueError\u001b[0m: Failed to find data adapter that can handle input: <class 'scipy.sparse._csr.csr_matrix'>, <class 'pandas.core.frame.DataFrame'>"
     ]
    }
   ],
   "source": [
    "tf.random.set_seed(42)  #first we set random seed\n",
    "model = tf.keras.Sequential([\n",
    "                             tf.keras.layers.Dense(1)\n",
    "])\n",
    "\n",
    "model.compile(loss = tf.keras.losses.mae, #mae stands for mean absolute error\n",
    "              optimizer = tf.keras.optimizers.SGD(), #stochastic GD\n",
    "              metrics = ['mae'])\n",
    "model.fit( df_preprocessed_general, df_target, epochs = 10)"
   ]
  },
  {
   "cell_type": "code",
   "execution_count": null,
   "id": "4ac1032a",
   "metadata": {},
   "outputs": [],
   "source": []
  }
 ],
 "metadata": {
  "kernelspec": {
   "display_name": "Python 3 (ipykernel)",
   "language": "python",
   "name": "python3"
  },
  "language_info": {
   "codemirror_mode": {
    "name": "ipython",
    "version": 3
   },
   "file_extension": ".py",
   "mimetype": "text/x-python",
   "name": "python",
   "nbconvert_exporter": "python",
   "pygments_lexer": "ipython3",
   "version": "3.9.13"
  }
 },
 "nbformat": 4,
 "nbformat_minor": 5
}
